<?xml version="1.0" ?>

<robot name="iRobot" xmlns:xacro="http://www.ros.org/wiki/xacro">
  <!-- MODELS -->
  <material name="iRobot/Green">
    <color rgba="0.0 1.0 0.0 1.0"/>
  </material>
  <material name="iRobot/Yellow">
    <color rgba="1.0 1.0 0.0 1.0"/>
  </material>
  <material name="iRobot/LightYellow">
    <color rgba="1.0 1.0 0.6 1.0"/>
  </material>
  <material name="iRobot/Blue">
    <color rgba="0.0 0.0 1.0 1.0"/>
  </material>
  <material name="iRobot/LightBlue">
    <color rgba="0.6 0.79 1.0 1.0"/>
  </material>
  <material name="iRobot/DarkGrey">
    <color rgba="0.31 0.31 0.31 1.0"/>
  </material>
  <material name="iRobot/LightGrey">
    <color rgba="0.83 0.83 0.83 1.0"/>
  </material>
  <material name="iRobot/MediumGrey">
    <color rgba="0.5 0.5 0.5 1.0"/>
  </material>
  <material name="iRobot/Black">
    <color rgba="0.0 0.0 0.0 1.0"/>
  </material>
  <material name="iRobot/Red">
    <color rgba="1.0 0.0 0.0 1.0"/>
  </material>
  <material name="iRobot/Orange">
    <color rgba="1.0 0.65 0.0 1.0"/>
  </material>
  <link name="robot_footprint"/>
  <joint name="ahla_joint_1" type="fixed">
      <origin xyz="0 0 0" rpy="0 0 0"/>
      <parent link="robot_footprint"/>
      <child link="base_link" />
  </joint>
  <link name="base_link">
    <inertial>
      <origin rpy="0 0 0" xyz="0 0 0"/>
      <mass value="0"/>
      <inertia ixx="0.0" ixy="0.0" ixz="0.0" iyy="0.0" iyz="0.0" izz="0.0"/>
    </inertial>
  </link>
  <joint name="base_joint" type="fixed">
    <origin rpy="0 0 0" xyz="0 0 0"/>
    <parent link="base_link"/>
    <child link="chassis"/>
  </joint>
  <link name="chassis">
    <inertial>
      <origin rpy="0 0 0" xyz="0 0 0"/>
      <mass value="10"/>
      <inertia ixx="0.425" ixy="0.0" ixz="0.0" iyy="0.425" iyz="0.0" izz="0.85"/>
    </inertial>
    <visual>
      <origin rpy="0 0 0" xyz="0 0 0"/>
      <geometry>
        <cylinder length="0.08" radius="0.17"/>
      </geometry>
      <material name="iRobot/LightGrey"/>
    </visual>
    <collision>
      <origin rpy="0 0 0" xyz="0 0 0"/>
      <geometry>
        <cylinder length="0.08" radius="0.17"/>
      </geometry>
    </collision>
  </link>
   <link name="cylinder_rod_link">
    <visual>
      <geometry>
        <cylinder length="1.0" radius="0.05"/>
      </geometry>
      <material name="blue"/>
    </visual>
    <collision>
      <geometry>
        <cylinder length="1.0" radius="0.05"/>
      </geometry>
    </collision>
  </link>

  <!-- Define a joint to connect the cylinder rod link to the chassis -->
  <joint name="cylinder_rod_joint" type="fixed">
    <parent link="chassis"/>
    <child link="cylinder_rod_link"/>
    <origin xyz="0.17 0 0.5" rpy="0 0 0"/>
  </joint>
  <joint name="left_axis_base_joint" type="fixed">
    <origin rpy="0 0 0" xyz="0 0.14 -0.02"/>
    <parent link="chassis"/>
    <child link="left_axis"/>
  </joint>
  <link name="left_axis">
    <inertial>
      <origin rpy="-1.57079632679 0 0" xyz="0 0 0"/>
      <mass value="0.001"/>
      <inertia ixx="6.25e-07" ixy="0.0" ixz="0.0" iyy="6.25e-07" iyz="0.0" izz="2.08333333333e-07"/>
    </inertial>
    <visual>
      <origin rpy="-1.57079632679 0 0" xyz="0 0 0"/>
      <geometry>
        <cylinder length="0.02" radius="0.0025"/>
      </geometry>
      <material name="iRobot/LightGrey"/>
    </visual>
    <collision>
      <origin rpy="-1.57079632679 0 0" xyz="0 0 0"/>
      <geometry>
        <cylinder length="0.02" radius="0.0025"/>
      </geometry>
    </collision>
  </link>
  <gazebo reference="left_axis_axis">
    <gravity>true</gravity>
    <material>Gazebo/Red</material>

  </gazebo>
  <joint name="left_wheel_rot_joint" type="continuous">
    <origin rpy="0 0 0" xyz="0 0 0"/>
    <axis xyz="0 1 0"/>
    <limit effort="100" velocity="100"/>
    <joint_properties damping="0.0" friction="0.0"/>
    <parent link="left_axis"/>
    <child link="left_wheel_link"/>
  </joint>
  <link name="left_wheel_link">
    <inertial>
      <origin rpy="-1.57079632679 0 0" xyz="0 0.01 0"/>
      <mass value="0.5"/>
      <inertia ixx="0.00375" ixy="0.0" ixz="0.0" iyy="0.00375" iyz="0.0" izz="0.00125"/>
    </inertial>
    <visual>
      <origin rpy="-1.57079632679 0 0" xyz="0 0 0"/>
      <geometry>
        <cylinder length="0.02" radius="0.03"/>
      </geometry>
      <material name="iRobot/Black"/>
    </visual>
    <collision>
      <origin rpy="-1.57079632679 0 0" xyz="0 0 0"/>
      <geometry>
        <cylinder length="0.02" radius="0.03"/>
      </geometry>
    </collision>
  </link>
  <gazebo reference="left_wheel_link">
    <gravity>true</gravity>
    <material>Gazebo/Grey</material>
  
  </gazebo>
  <joint name="right_axis_base_joint" type="fixed">
    <origin rpy="0 0 0" xyz="0 -0.14 -0.02"/>
    <parent link="chassis"/>
    <child link="right_axis"/>
  </joint>
  <link name="right_axis">
    <inertial>
      <origin rpy="-1.57079632679 0 0" xyz="0 0 0"/>
      <mass value="0.001"/>
      <inertia ixx="6.25e-07" ixy="0.0" ixz="0.0" iyy="6.25e-07" iyz="0.0" izz="2.08333333333e-07"/>
    </inertial>
    <visual>
      <origin rpy="-1.57079632679 0 0" xyz="0 0 0"/>
      <geometry>
        <cylinder length="0.02" radius="0.0025"/>
      </geometry>
      <material name="iRobot/LightGrey"/>
    </visual>
    <collision>
      <origin rpy="-1.57079632679 0 0" xyz="0 0 0"/>
      <geometry>
        <cylinder length="0.02" radius="0.0025"/>
      </geometry>
    </collision>
  </link>
  <gazebo reference="right_axis_axis">
    <gravity>true</gravity>
    <material>Gazebo/Red</material>

  </gazebo>
  <joint name="right_wheel_rot_joint" type="continuous">
    <origin rpy="0 0 0" xyz="0 0 0"/>
    <axis xyz="0 1 0"/>
    <limit effort="100" velocity="100"/>
    <joint_properties damping="0.0" friction="0.0"/>
    <parent link="right_axis"/>
    <child link="right_wheel_link"/>
  </joint>
  <link name="right_wheel_link">
    <inertial>
      <origin rpy="-1.57079632679 0 0" xyz="0 0.01 0"/>
      <mass value="0.5"/>
      <inertia ixx="0.00375" ixy="0.0" ixz="0.0" iyy="0.00375" iyz="0.0" izz="0.00125"/>
    </inertial>
    <visual>
      <origin rpy="-1.57079632679 0 0" xyz="0 0 0"/>
      <geometry>
        <cylinder length="0.02" radius="0.03"/>
      </geometry>
      <material name="iRobot/Black"/>
    </visual>
    <collision>
      <origin rpy="-1.57079632679 0 0" xyz="0 0 0"/>
      <geometry>
        <cylinder length="0.02" radius="0.03"/>
      </geometry>
    </collision>
  </link>
  <gazebo reference="right_wheel_link">
    <gravity>true</gravity>
    <material>Gazebo/Grey</material>

  </gazebo>
  <joint name="sphere_joint1" type="revolute">
    <origin rpy="0 0 0" xyz="0.14 0 -0.04"/>
    <axis xyz="0 0 1"/>
    <limit effort="100" lower="0" upper="0" velocity="100"/>
    <parent link="chassis"/>
    <child link="sphere1"/>
  </joint>
  <link name="sphere1">
    <inertial>
      <origin rpy="0 0 0" xyz="0 0 0"/>
      <mass value="0.3"/>
      <inertia ixx="0.0012" ixy="0.0" ixz="0.0" iyy="0.0012" iyz="0.0" izz="0.0012"/>
    </inertial>
    <visual>
      <origin rpy="0 0 0" xyz="0 0 0"/>
      <geometry>
        <sphere radius="0.01"/>
      </geometry>
      <material name="iRobot/Black"/>
    </visual>
    <collision>
      <origin rpy="0 0 0" xyz="0 0 0"/>
      <geometry>
        <sphere radius="0.01"/>
      </geometry>
    </collision>
  </link>
  <joint name="sphere_joint2" type="revolute">
    <origin rpy="0 0 0" xyz="-0.14 0 -0.04"/>
    <axis xyz="0 0 1"/>
    <limit effort="100" lower="0" upper="0" velocity="100"/>
    <parent link="chassis"/>
    <child link="sphere2"/>
  </joint>
  <link name="sphere2">
    <inertial>
      <origin rpy="0 0 0" xyz="0 0 0"/>
      <mass value="0.3"/>
      <inertia ixx="0.0012" ixy="0.0" ixz="0.0" iyy="0.0012" iyz="0.0" izz="0.0012"/>
    </inertial>
    <visual>
      <origin rpy="0 0 0" xyz="0 0 0"/>
      <geometry>
        <sphere radius="0.01"/>
      </geometry>
      <material name="iRobot/Black"/>
    </visual>
    <collision>
      <origin rpy="0 0 0" xyz="0 0 0"/>
      <geometry>
        <sphere radius="0.01"/>
      </geometry>
    </collision>
  </link>
  <!-- Laser link and plugin -->
  <joint name="hokuyo_laser_joint" type="fixed">
    <axis xyz="0 0 1"/>
    <origin rpy="0 0 0" xyz="0 0 0.06"/>
    <parent link="base_link"/>
    <child link="hokuyo_laser_link"/>
  </joint>
  <link name="hokuyo_laser_link">
    <collision>
      <origin rpy="0 0 0" xyz="0 0 0"/>
      <geometry>
        <cylinder length="0.04" radius="0.045"/>
      </geometry>
    </collision>
    <visual>
      <origin rpy="0 0 0" xyz="0 0 0"/>
      <geometry>
        <cylinder length="0.04" radius="0.045"/>
      </geometry>
      <material name="iRobot/LightBlue"/>
    </visual>
    <inertial>
      <mass value="1e-5"/>
      <origin rpy="0 0 0" xyz="0 0 0"/>
      <inertia ixx="1e-6" ixy="0" ixz="0" iyy="1e-6" iyz="0" izz="1e-6"/>
    </inertial>
  </link>

  <gazebo reference="hokuyo_laser_link">
    <sensor type="ray" name="head_hokuyo_sensor">
      <pose>0 0 0 0 0 0</pose>
      <visualize>true</visualize>
      <update_rate>40</update_rate>
      <ray>
        <scan>
          <horizontal>
            <samples>770</samples>
            <resolution>1</resolution>
            <min_angle>-1.5708</min_angle>
            <max_angle>1.5708</max_angle>
          </horizontal>
        </scan>
        <range>
          <min>0.10</min>
          <max>10.0</max>
          <resolution>0.01</resolution>
        </range>
        <noise>
          <type>gaussian</type>
          <mean>0.0</mean>
          <stddev>0.01</stddev>
        </noise>
      </ray>
      <plugin filename="libgazebo_ros_laser.so" name="gazebo_ros_head_hokuyo_controller">
        <robotNamespace/>
        <topicName>laser_scan</topicName>
        <frameName>hokuyo_laser_link</frameName>
      </plugin>
    </sensor>
  </gazebo>

  <!--    <xacro:model_shelf name="first_shelf" 
                       parent="chassis"
                       height="0.15">
    </xacro:model_shelf>-->
  <!--    <xacro:model_shelf name="second_shelf" 
                       parent="first_shelf"
                       height="0.25">
    </xacro:model_shelf>
    -->


  <gazebo reference="sphere1">
    <gravity>true</gravity>
    <material>Gazebo/Grey</material>

  </gazebo>
  <gazebo reference="sphere2">
    <gravity>true</gravity>
    <material>Gazebo/Grey</material>

  </gazebo>
  <gazebo reference="chassis">
    <gravity>true</gravity>
    <material>Gazebo/Yellow</material>
  </gazebo>

  <gazebo>
    <plugin name="differential_drive_controller" filename="libgazebo_ros_diff_drive.so">
      <updateRate>20</updateRate>
      <robotBaseFrame>robot_footprint</robotBaseFrame>
      <leftJoint>left_wheel_rot_joint</leftJoint>
      <rightJoint>right_wheel_rot_joint</rightJoint>
      <wheelSeparation>0.28</wheelSeparation>
      <wheelDiameter>0.06</wheelDiameter>
      <wheelAcceleration>2.0</wheelAcceleration>
      <wheelTorque>100</wheelTorque>
      <commandTopic>cmd_vel</commandTopic>
      <odometryTopic>odom</odometryTopic>
      <odometryFrame>odom</odometryFrame>
      <odometrySource>1</odometrySource>
      <publishWheelTF>false</publishWheelTF>
      <publishOdomTF>true</publishOdomTF>
      <publishOdom>true</publishOdom>
      <publishWheelJointState>true</publishWheelJointState>
      <legacyMode>false</legacyMode>
      <alwaysOn>true</alwaysOn>
    </plugin>
  </gazebo>
</robot>
